Workbook

Sheet Dashboard
A1: GLOBAL E-COMMERCE SALES DASHBOARD
B4: TOTAL SALES | C4: =SUM('Global Ecommerce Sales'!L:L) -> 484559.34 | E4: TOTAL PROFIT | F4: =SUM('Global Ecommerce Sales'!N:N) -> 158872.32 | H4: TOTAL ORDERS | I4: =COUNTA('Global Ecommerce Sales'!A:A)-1 -> 2000 | K4: TOTAL CUSTOMERS | L4: =SUMPRODUCT(('Global Ecommerce Sales'!C2:C2001<>"")/COUNTIF('Global Ecommerce Sales'!C2:C2001,'Global Ecommerce Sales'!C2:C2001&"")) -> 1534 | N4: TOTAL QUANTITY | O4: =SUM('Global Ecommerce Sales'!I:I) -> 7115

Sheet Global Ecommerce Sales
A1: Order_ID | B1: Order_Date | C1: Customer_Name | D1: Customer_Segment | E1: Country | F1: Region | G1: Product_Category | H1: Product_Name | I1: Quantity | J1: Unit_Price | K1: Discount_Percent | L1: Total_Sales | M1: Shipping_Cost | N1: Profit | O1: Payment_Method | P1: Sales Before Discount | Q1: Profit Margin % | R1: Orders Values
A2: ORD-11121 | B2: 44928 | C2: Karen Suzuki | D2: Corporate | E2: United States | F2: North America | G2: Technology | H2: Wireless Bluetooth Headphones | I2: 3 | J2: 99.43 | K2: 0 | L2: 298.29 | M2: 9.31 | N2: 124.92 | O2: Cash on Delivery | P2: =Table1[Quantity]*Table1[Unit_Price] -> 298.29 | Q2: =Table1[Profit]/Table1[Total_Sales] -> 0.41878709 | R2: =Table1[Total_Sales]+Table1[Shipping_Cost] -> 307.6
A3: ORD-11244 | B3: 44928 | C3: John Johansson | D3: Corporate | E3: Spain | F3: Europe | G3: Technology | H3: Mechanical Gaming Keyboard | I3: 4 | J3: 97.93 | K3: 20 | L3: 313.38 | M3: 14.31 | N3: 83.62 | O3: Cash on Delivery | P3: =Table1[Quantity]*Table1[Unit_Price] -> 391.72 | Q3: =Table1[Profit]/Table1[Total_Sales] -> 0.2668326 | R3: =Table1[Total_Sales]+Table1[Shipping_Cost] -> 327.69
A4: ORD-10325 | B4: 44929 | C4: Jessica Garcia | D4: Consumer | E4: Mexico | F4: North America | G4: Office Supplies | H4: Binder Clips Assorted 48pc | I4: 2 | J4: 10.74 | K4: 0 | L4: 21.48 | M4: 8.12 | N4: 3.69 | O4: Credit Card | P4: =Table1[Quantity]*Table1[Unit_Price] -> 21.48 | Q4: =Table1[Profit]/Table1[Total_Sales] -> 0.17178771 | R4: =Table1[Total_Sales]+Table1[Shipping_Cost] -> 29.6
A5: ORD-10467 | B5: 44929 | C5: Clara Taylor | D5: Corporate | E5: Italy | F5: Europe | G5: Technology | H5: Webcam HD 1080p | I5: 2 | J5: 61.86 | K5: 15 | L5: 105.16 | M5: 10.79 | N5: 26.32 | O5: PayPal | P5: =Table1[Quantity]*Table1[Unit_Price] -> 123.72 | Q5: =Table1[Profit]/Table1[Total_Sales] -> 0.25028528 | R5: =Table1[Total_Sales]+Table1[Shipping_Cost] -> 115.95
A6: ORD-11454 | B6: 44931 | C6: Felix Thomas | D6: Consumer | E6: Italy | F6: Europe | G6: Furniture | H6: Standing Desk Converter | I6: 4 | J6: 330.67 | K6: 20 | L6: 1058.14 | M6: 11.09 | N6: 253.44 | O6: Credit Card | P6: =Table1[Quantity]*Table1[Unit_Price] -> 1322.68 | Q6: =Table1[Profit]/Table1[Total_Sales] -> 0.23951462 | R6: =Table1[Total_Sales]+Table1[Shipping_Cost] -> 1069.23
A7: ORD-11746 | B7: 44931 | C7: Fatima Suzuki | D7: Consumer | E7: Mexico | F7: North America | G7: Furniture | H7: Bookshelf 5-Tier | I7: 1 | J7: 61.93 | K7: 10 | L7: 55.74 | M7: 5.88 | N7: 12.7 | O7: PayPal | P7: =Table1[Quantity]*Table1[Unit_Price] -> 61.93 | Q7: =Table1[Profit]/Table1[Total_Sales] -> 0.22784356 | R7: =Table1[Total_Sales]+Table1[Shipping_Cost] -> 61.62
A8: ORD-11162 | B8: 44932 | C8: Felix Rodriguez | D8: Home Office | E8: United States | F8: North America | G8: Office Supplies | H8: Premium Notebook Set A5 | I8: 2 | J8: 15.03 | K8: 5 | L8: 28.56 | M8: 6.59 | N8: 8.44 | O8: PayPal | P8: =Table1[Quantity]*Table1[Unit_Price] -> 30.06 | Q8: =Table1[Profit]/Table1[Total_Sales] -> 0.29551821 | R8: =Table1[Total_Sales]+Table1[Shipping_Cost] -> 35.15
A9: ORD-11271 | B9: 44932 | C9: Ayumi Ferrari | D9: Home Office | E9: Nigeria | F9: Middle East & Africa | G9: Technology | H9: Laptop Stand Adjustable | I9: 2 | J9: 33.91 | K9: 10 | L9: 61.04 | M9: 14.38 | N9: 9.36 | O9: Bank Transfer | P9: =Table1[Quantity]*Table1[Unit_Price] -> 67.82 | Q9: =Table1[Profit]/Table1[Total_Sales] -> 0.15334207 | R9: =Table1[Total_Sales]+Table1[Shipping_Cost] -> 75.42
A10: ORD-11702 | B10: 44932 | C10: Thomas Smith | D10: Consumer | E10: China | F10: Asia Pacific | G10: Furniture | H10: Standing Desk Converter | I10: 2 | J10: 334.11 | K10: 5 | L10: 634.81 | M10: 11.92 | N10: 221.96 | O10: Bank Transfer | P10: =Table1[Quantity]*Table1[Unit_Price] -> 668.22 | Q10: =Table1[Profit]/Table1[Total_Sales] -> 0.34964793 | R10: =Table1[Total_Sales]+Table1[Shipping_Cost] -> 646.73
A11: ORD-10847 | B11: 44933 | C11: Ali Rodriguez | D11: Consumer | E11: Saudi Arabia | F11: Middle East & Africa | G11: Furniture | H11: Folding Table Portable | I11: 1 | J11: 58.77 | K11: 5 | L11: 55.83 | M11: 12.03 | N11: 8.54 | O11: Credit Card | P11: =Table1[Quantity]*Table1[Unit_Price] -> 58.77 | Q11: =Table1[Profit]/Table1[Total_Sales] -> 0.15296436 | R11: =Table1[Total_Sales]+Table1[Shipping_Cost] -> 67.86
A12: ORD-10446 | B12: 44934 | C12: Raj Martinez | D12: Corporate | E12: Colombia | F12: South America | G12: Clothing & Accessories | H12: Leather Wallet Minimalist | I12: 2 | J12: 38.91 | K12: 15 | L12: 66.15 | M12: 14.25 | N12: 12.99 | O12: Credit Card | P12: =Table1[Quantity]*Table1[Unit_Price] -> 77.82 | Q12: =Table1[Profit]/Table1[Total_Sales] -> 0.19637188 | R12: =Table1[Total_Sales]+Table1[Shipping_Cost] -> 80.4
A13: ORD-11499 | B13: 44934 | C13: Kenji Rossi | D13: Corporate | E13: Spain | F13: Europe | G13: Office Supplies | H13: Paper Clips Box 500pc | I13: 3 | J13: 7.8 | K13: 10 | L13: 21.06 | M13: 12.61 | N13: -2.08 | O13: Cash on Delivery | P13: =Table1[Quantity]*Table1[Unit_Price] -> 23.4 | Q13: =Table1[Profit]/Table1[Total_Sales] -> -0.098765432 | R13: =Table1[Total_Sales]+Table1[Shipping_Cost] -> 33.67
... A2001: ORD-11701 | B2001: 46022 | C2001: Susan Russo | D2001: Home Office | E2001: South Korea | F2001: Asia Pacific | G2001: Clothing & Accessories | H2001: Sports Water Bottle 750ml | I2001: 11 | J2001: 28.27 | K2001: 0 | L2001: 310.97 | M2001: 36.23 | N2001: 119.26 | O2001: Credit Card | P2001: =Table1[Quantity]*Table1[Unit_Price] -> 310.97 | Q2001: =Table1[Profit]/Table1[Total_Sales] -> 0.38350966 | R2001: =Table1[Total_Sales]+Table1[Shipping_Cost] -> 347.2

Sheet Pivot_Customer
A3: Row Labels | B3: Sum of Total_Sales
A4: Consumer | B4: 256287.74
A5: Corporate | B5: 146050.39
A6: Home Office | B6: 82221.21
A7: Grand Total | B7: 484559.34

Sheet Pivot_Region
A2: Row Labels | B2: Sum of Total_Sales
A3: Europe | B3: 137006.2
A4: North America | B4: 133876.38
A5: Asia Pacific | B5: 121707.51
A6: South America | B6: 46051.13
A7: Middle East & Africa | B7: 45918.12
A8: Grand Total | B8: 484559.34

Sheet Pivot_Catogory
A2: Row Labels | B2: Sum of Profit
A3: Furniture | B3: 81171.57
A4: Technology | B4: 48268.65
A5: Clothing & Accessories | B5: 26112.94
A6: Office Supplies | B6: 3319.16
A7: Grand Total | B7: 158872.32

Sheet Pivot_Monthly
A2: Row Labels | B2: Sum of Profit
A3: 2023
A4: Qtr1
A5: Jan | B5: 3573.01
A6: Feb | B6: 5980.06
A7: Mar | B7: 5718.77
A8: Qtr2
A9: Apr | B9: 3994.25
A10: May | B10: 2591.86
A11: Jun | B11: 5240.34
A12: Qtr3
A13: Jul | B13: 5195.97
A14: Aug | B14: 4216.32
A15: Sep | B15: 3577
A16: Qtr4
A17: Oct | B17: 5573.05
A18: Nov | B18: 2469.77
A19: Dec | B19: 5023.34
A20: 2024
A21: Qtr1
A22: Jan | B22: 2490.14
A23: Feb | B23: 4131.26
A24: Mar | B24: 3583.31
A25: Qtr2
A26: Apr | B26: 4900.65
A27: May | B27: 5909.3
A28: Jun | B28: 3051.84
A29: Qtr3
A30: Jul | B30: 5137.37
A31: Aug | B31: 3198.94
A32: Sep | B32: 3094.84
A33: Qtr4
A34: Oct | B34: 5443.33
A35: Nov | B35: 5630.78
A36: Dec | B36: 5044.35
A37: 2025
A38: Qtr1
A39: Jan | B39: 4309.77
A40: Feb | B40: 2430.75
A41: Mar | B41: 2489.6
...

Sheet Pivot_Product
A2: Row Labels | B2: Sum of Total_Sales
A3: Standing Desk Converter | B3: 46614.22
A4: Ergonomic Office Chair | B4: 45405.15
A5: Corner L-Shaped Desk | B5: 41070.48
A6: Mesh Back Task Chair | B6: 38179.77
A7: Wireless Bluetooth Headphones | B7: 28258.7
A8: Mechanical Gaming Keyboard | B8: 24072.42
A9: Filing Cabinet 3-Drawer | B9: 23108.01
A10: Folding Table Portable | B10: 18663.13
A11: Portable External SSD 1TB | B11: 18065.3
A12: Bookshelf 5-Tier | B12: 17741.59
A13: Grand Total | B13: 301178.77

Sheet Pivot_Payment
A2: Row Labels | B2: Sum of Total_Sales
A3: Credit Card | B3: 192717.89
A4: PayPal | B4: 143112.87
A5: Cash on Delivery | B5: 77129.54
A6: Bank Transfer | B6: 71599.04
A7: Grand Total | B7: 484559.34

Sheet Discount vs Profit
A1: Discount_Percent | B1: Profit
A2: 0 | B2: 25.91
A3: 20 | B3: 25.41
A4: 0 | B4: 80.55
A5: 15 | B5: -1.76
A6: 20 | B6: 14.04
A7: 10 | B7: 43.67
A8: 5 | B8: 17.23
A9: 10 | B9: 160.9
A10: 5 | B10: 4.66
A11: 5 | B11: 5.62
A12: 15 | B12: 22.54
A13: 10 | B13: 148.24
... A22: 25 | B22: 119.26
A23: 10
A24: 0
A25: 5
A26: 10
A27: 20
A28: 5
A29: 0
A30: 0
A31: 5
A32: 5
A33: 15
A34: 5
... A2001: 0

Sheet Sheet9
A3: Row Labels | B3: Sum of Profit
A4: ORD-10001 | B4: 3.56
A5: ORD-10002 | B5: 40.13
A6: ORD-10003 | B6: 24.98
A7: ORD-10004 | B7: 413.7
A8: ORD-10005 | B8: -0.01
A9: ORD-10006 | B9: -0.71
A10: ORD-10007 | B10: 139.12
A11: ORD-10008 | B11: -3.55
A12: ORD-10009 | B12: 37.46
A13: ORD-10010 | B13: 174.52
A14: ORD-10011 | B14: 646.52
A15: ORD-10012 | B15: 11.46
... A2004: Grand Total | B2004: 158872.32
